Workbook

Sheet لیست پرسنل
A1: username | B1: personnel_code | C1: company | D1: unit | E1: national_code | F1: current_location
A2: مسلم میدانی | B2: 1946 | C2: فکورصنعت | D2: انبار | F2: توسعه فولاد (362)
A3: محمدرضا کیوان | B3: 1309 | C3: فکورصنعت | D3: مالی - اداری | F3: توسعه فولاد (362)
A4: محمد سلیم نیا | B4: 2224 | C4: فکورصنعت | D4: سرپرست واحد اکسیژن | F4: توسعه فولاد (362)
A5: ساسان انصاری | B5: 4001002 | C5: فکورصنعت | D5: ایمنی | F5: توسعه فولاد (362)
A6: سید جواد موسوی | B6: 0 | C6: نقشه برداری | D6: نقشه برداری | F6: توسعه فولاد (362)
A7: مانیتورینگ توسعه فولاد | B7: 0 | F7: توسعه فولاد (362)
A8: سبحان سلجوقی | B8: 20519 | C8: گهر کوشان سپهر | D8: اداری | E8: 3060349347 | F8: توسعه فولاد (362)
A9: مجید شکیبایی | B9: 1535 | C9: فکورصنعت | D9: کنترل پروژه | F9: توسعه فولاد (362)
A10: هومن حسین پور | B10: 683 | C10: فکورصنعت | D10: نظارت سیویل | F10: توسعه فولاد (362)
A11: محسن صالحی | B11: 20564 | C11: گهر کوشان سپهر | D11: کارمند اداری آهک | F11: توسعه فولاد (362)
A12: محمد رضا ایرانمنش | B12: 5031 | C12: فکورصنعت | D12: کنترل کیفیت | F12: توسعه فولاد (362)
A13: عرفان باجلانی | B13: 4020606 | C13: فکورصنعت | D13: اداری | E13: 3341380140 | F13: توسعه فولاد (362)
A14: هادی محمد نژاد | B14: 100566 | C14: مهرفام | D14: کنترل کیفیت | E14: 3071218354 | F14: توسعه فولاد (362)
A15: وحید حسینی | B15: 100599 | C15: مهرفام | D15: دفتر فنی سیویل | E15: 2391721341 | F15: توسعه فولاد (362)
A16: غلامرضا سپیانی | B16: 0 | C16: مهرفام | D16: سیویل | E16: 1129608591 | F16: توسعه فولاد (362)
A17: حمزه مسلمی | B17: 4500 | C17: فکورصنعت | D17: ابزار دقیق | F17: توسعه فولاد (362)
A18: ایمان فتحی | B18: 20473 | C18: گهر کوشان سپهر | D18: ایمنی | F18: توسعه فولاد (362)
A19: مجید بلوردی | B19: 5022 | C19: فکورصنعت | D19: انبار | F19: توسعه فولاد (362)
A20: آذر نیک اختر | B20: 2210 | C20: فکورصنعت | D20: سرپرست آی تی | F20: توسعه فولاد (362)
A21: واحد آی تی | F21: توسعه فولاد (362)
A22: ابوالفضل پور زیدآبادی | B22: 20628 | C22: گهر کوشان سپهر | D22: انبار | F22: توسعه فولاد (362)
A23: حجت عزت نیا | C23: فکورصنعت | D23: ماشین آلات سنگین | F23: توسعه فولاد (362)
A24: محمد خواجوئی نژاد | B24: 2237 | C24: فکورصنعت | D24: آی تی | F24: توسعه فولاد (362)
A25: محمد خواجوئی نژاد | B25: 0 | C25: مهرفام | D25: مکانیک | F25: توسعه فولاد (362)
A26: سالن کنفرانس نظارت | F26: توسعه فولاد (362)
A27: خسرو بقایی | B27: 99123 | C27: فکورصنعت | D27: کنترل کیفیت | F27: توسعه فولاد (362)
A28: مجتبی علی پور زارعی | B28: 20255 | C28: گهر کوشان سپهر | D28: کنترل کیفیت | F28: توسعه فولاد (362)
A29: کامیار صدیقی | B29: 100513 | C29: مهرفام | D29: اجرا | F29: توسعه فولاد (362)
A30: پیمان جعفری | B30: 5027 | C30: فکورصنعت | F30: توسعه فولاد (362)
A31: امیررضا اسحاقی | B31: 20361 | C31: گهر کوشان سپهر | D31: انبار-آهک | F31: توسعه فولاد (362)
A32: سیاوش دالوند | B32: 0 | C32: مهرفام | D32: کنترل کیفیت | F32: توسعه فولاد (362)
A33: بنفشه صادقی | B33: 5023 | C33: فکورصنعت | F33: توسعه فولاد (362)
A34: محسن مومنی | B34: 990701 | C34: فکورصنعت | D34: دفتر فنی | F34: توسعه فولاد (362)
A35: سالن کنفرانس | F35: توسعه فولاد (362)
A36: حمیدرضا قدرتی | B36: 993 | C36: فکورصنعت | D36: سرپرست واحد آهک | F36: توسعه فولاد (362)
A37: امیر عباسی | B37: 0 | C37: نیرو پژوه سهند | E37: 1960407937 | F37: توسعه فولاد (362)
A38: محسن رضوانی | D38: حراست توسعه | F38: توسعه فولاد (362)
A39: پارسا محمودی پور | B39: 0 | C39: فرزان-MC | D39: نظارت سیویل | F39: توسعه فولاد (362)
A40: سالن کنفرانس بزرگ | F40: توسعه فولاد (362)
...

Sheet دوربین های فاقدکد
A1: کد سایت | B1: ردیف | C1: تحویل گیرنده اول | D1: شرکت | E1: واحد | F1: کد پرسنلی | G1: محل استقرار | H1: کد شناسایی سیستم | I1: گروه بندی | J1: مدل | K1: سریال | L1: کد اموال | M1: تحویل گیرنده دوم | N1: تحویل گیرنده -1 | O1: تحویل گیرنده -2 | P1: توضیحات | Q1: مختوم شده | R1: تاریخ اختتام
A2: AN_SiR | C2: آذر نیک اختر | D2: =VLOOKUP(C2,'لیست پرسنل'!$A$1:$E$1004,3,FALSE) -> فکورصنعت | E2: =VLOOKUP(C2,'لیست پرسنل'!$A$1:$E$1004,4,FALSE) -> سرپرست آی تی | F2: =VLOOKUP(C2,'لیست پرسنل'!$A$1:$E$1004,2,FALSE) -> 2210 | G2: انبار منطقه ای سیرجان | I2: دوربین مداربسته | J2: DAHUA DH-IPC-HDW2439 | K2: 7E05100PAGA7EAB | L2: فاقد اموال | N2: خوابگاه دماوند سیرجان جمع اوری شد | P2: تحویل آقای صادقی جهت تعمیر به علت خرابی سوکت شبکه
A3: AN_SiR | C3: رضا کاظمی | D3: =VLOOKUP(C3,'لیست پرسنل'!$A$1:$E$1004,3,FALSE) -> نظارت برسو | E3: =VLOOKUP(C3,'لیست پرسنل'!$A$1:$E$1004,4,FALSE) -> مدیر برسو | F3: =VLOOKUP(C3,'لیست پرسنل'!$A$1:$E$1004,2,FALSE) -> 0 | G3: انبار منطقه ای سیرجان | I3: دوربین مداربسته | J3: HIK VISION DS-2CD1067G2-L | K3: AG7241550 | L3: فاقد اموال | P3: نصب در انبار شهر
A4: AN_SiR | C4: رضا کاظمی | D4: =VLOOKUP(C4,'لیست پرسنل'!$A$1:$E$1004,3,FALSE) -> نظارت برسو | E4: =VLOOKUP(C4,'لیست پرسنل'!$A$1:$E$1004,4,FALSE) -> مدیر برسو | F4: =VLOOKUP(C4,'لیست پرسنل'!$A$1:$E$1004,2,FALSE) -> 0 | G4: انبار منطقه ای سیرجان | I4: دوربین مداربسته | J4: HIK VISION DS-2CD1067G2-L | K4: AG7241534 | L4: فاقد اموال | P4: نصب در انبار شهر
A5: AN_SiR | C5: رضا کاظمی | D5: =VLOOKUP(C5,'لیست پرسنل'!$A$1:$E$1004,3,FALSE) -> نظارت برسو | E5: =VLOOKUP(C5,'لیست پرسنل'!$A$1:$E$1004,4,FALSE) -> مدیر برسو | F5: =VLOOKUP(C5,'لیست پرسنل'!$A$1:$E$1004,2,FALSE) -> 0 | G5: انبار منطقه ای سیرجان | I5: دوربین مداربسته | J5: HIK VISION DS-2CD1067G2-L | K5: AG7241524 | L5: فاقد اموال | P5: نصب در انبار شهر
A6: AN_SiR | C6: رضا کاظمی | D6: =VLOOKUP(C6,'لیست پرسنل'!$A$1:$E$1004,3,FALSE) -> نظارت برسو | E6: =VLOOKUP(C6,'لیست پرسنل'!$A$1:$E$1004,4,FALSE) -> مدیر برسو | F6: =VLOOKUP(C6,'لیست پرسنل'!$A$1:$E$1004,2,FALSE) -> 0 | G6: انبار منطقه ای سیرجان | I6: دوربین مداربسته | J6: HIK VISION DS-2CD1067G2-L | K6: AG7241536 | L6: فاقد اموال | P6: نصب در انبار شهر
A7: AN_SiR | C7: رضا کاظمی | D7: =VLOOKUP(C7,'لیست پرسنل'!$A$1:$E$1004,3,FALSE) -> نظارت برسو | E7: =VLOOKUP(C7,'لیست پرسنل'!$A$1:$E$1004,4,FALSE) -> مدیر برسو | F7: =VLOOKUP(C7,'لیست پرسنل'!$A$1:$E$1004,2,FALSE) -> 0 | G7: انبار منطقه ای سیرجان | I7: دوربین مداربسته | J7: HIK VISION DS-2CD1067G2-L | K7: AG7241548 | L7: فاقد اموال | P7: نصب در انبار شهر
A8: AN_SiR | C8: رضا کاظمی | D8: =VLOOKUP(C8,'لیست پرسنل'!$A$1:$E$1004,3,FALSE) -> نظارت برسو | E8: =VLOOKUP(C8,'لیست پرسنل'!$A$1:$E$1004,4,FALSE) -> مدیر برسو | F8: =VLOOKUP(C8,'لیست پرسنل'!$A$1:$E$1004,2,FALSE) -> 0 | G8: انبار منطقه ای سیرجان | I8: دوربین مداربسته | J8: HIK VISION DS-2CD1067G2-L | K8: AG7241546 | L8: فاقد اموال | P8: نصب در انبار شهر
A9: AN_SiR | C9: رضا کاظمی | D9: =VLOOKUP(C9,'لیست پرسنل'!$A$1:$E$1004,3,FALSE) -> نظارت برسو | E9: =VLOOKUP(C9,'لیست پرسنل'!$A$1:$E$1004,4,FALSE) -> مدیر برسو | F9: =VLOOKUP(C9,'لیست پرسنل'!$A$1:$E$1004,2,FALSE) -> 0 | G9: انبار منطقه ای سیرجان | I9: دوربین مداربسته | J9: HIK VISION DS-2CD1067G2-L | K9: AG7241545 | L9: فاقد اموال | P9: نصب در انبار شهر
A10: AN_SiR | C10: رضا کاظمی | D10: =VLOOKUP(C10,'لیست پرسنل'!$A$1:$E$1004,3,FALSE) -> نظارت برسو | E10: =VLOOKUP(C10,'لیست پرسنل'!$A$1:$E$1004,4,FALSE) -> مدیر برسو | F10: =VLOOKUP(C10,'لیست پرسنل'!$A$1:$E$1004,2,FALSE) -> 0 | G10: انبار منطقه ای سیرجان | I10: دوربین مداربسته | J10: HIK VISION DS-2CD1067G2-L | K10: AG7241549 | L10: فاقد اموال | P10: نصب در انبار شهر
A11: AN362 | C11: آذر نیک اختر | D11: =VLOOKUP(C11,'لیست پرسنل'!$A$1:$E$1004,3,FALSE) -> فکورصنعت | E11: =VLOOKUP(C11,'لیست پرسنل'!$A$1:$E$1004,4,FALSE) -> سرپرست آی تی | F11: =VLOOKUP(C11,'لیست پرسنل'!$A$1:$E$1004,2,FALSE) -> 2210 | G11: توسعه فولاد (362) | I11: دوربین مداربسته | J11: DAHUA DH-IPC-HFW2831TP-AS-S10 | K11: 9C0B450PAG2D260 | L11: فاقد کد اموال
A12: AN362 | C12: آذر نیک اختر | D12: =VLOOKUP(C12,'لیست پرسنل'!$A$1:$E$1004,3,FALSE) -> فکورصنعت | E12: =VLOOKUP(C12,'لیست پرسنل'!$A$1:$E$1004,4,FALSE) -> سرپرست آی تی | F12: =VLOOKUP(C12,'لیست پرسنل'!$A$1:$E$1004,2,FALSE) -> 2210 | G12: توسعه فولاد (362) | I12: دوربین مداربسته | J12: DAHUA DH-IPC-HFW2831TP-AS-S11 | K12: 9C0B450PAG97A29 | L12: فاقد کد اموال
A13: AN362 | C13: آذر نیک اختر | D13: =VLOOKUP(C13,'لیست پرسنل'!$A$1:$E$1004,3,FALSE) -> فکورصنعت | E13: =VLOOKUP(C13,'لیست پرسنل'!$A$1:$E$1004,4,FALSE) -> سرپرست آی تی | F13: =VLOOKUP(C13,'لیست پرسنل'!$A$1:$E$1004,2,FALSE) -> 2210 | G13: توسعه فولاد (362) | I13: دوربین مداربسته | J13: DAHUA DH-IPC-HFW2831TP-AS-S2 | K13: 7F02122PAG6F134 | L13: فاقد کد اموال
A14: AN362 | C14: آذر نیک اختر | D14: =VLOOKUP(C14,'لیست پرسنل'!$A$1:$E$1004,3,FALSE) -> فکورصنعت | E14: =VLOOKUP(C14,'لیست پرسنل'!$A$1:$E$1004,4,FALSE) -> سرپرست آی تی | F14: =VLOOKUP(C14,'لیست پرسنل'!$A$1:$E$1004,2,FALSE) -> 2210 | G14: توسعه فولاد (362) | I14: دوربین مداربسته | J14: DAHUA DH-IPC-HFW2831TP-AS-S3 | K14: 7F02122PAG8763C | L14: فاقد کد اموال
A15: AN362 | C15: آذر نیک اختر | D15: =VLOOKUP(C15,'لیست پرسنل'!$A$1:$E$1004,3,FALSE) -> فکورصنعت | E15: =VLOOKUP(C15,'لیست پرسنل'!$A$1:$E$1004,4,FALSE) -> سرپرست آی تی | F15: =VLOOKUP(C15,'لیست پرسنل'!$A$1:$E$1004,2,FALSE) -> 2210 | G15: توسعه فولاد (362) | I15: دوربین مداربسته | J15: DAHUA DH-IPC-HFW2831TP-AS-S4 | K15: 9C0B450PAGF276C | L15: فاقد کد اموال
A16: AN362 | C16: آذر نیک اختر | D16: =VLOOKUP(C16,'لیست پرسنل'!$A$1:$E$1004,3,FALSE) -> فکورصنعت | E16: =VLOOKUP(C16,'لیست پرسنل'!$A$1:$E$1004,4,FALSE) -> سرپرست آی تی | F16: =VLOOKUP(C16,'لیست پرسنل'!$A$1:$E$1004,2,FALSE) -> 2210 | G16: توسعه فولاد (362) | I16: دوربین مداربسته | J16: DAHUA DH-IPC-HFW2831TP-AS-S5 | K16: 9C0B450PAG7F53E | L16: فاقد کد اموال
A17: AN362 | C17: آذر نیک اختر | D17: =VLOOKUP(C17,'لیست پرسنل'!$A$1:$E$1004,3,FALSE) -> فکورصنعت | E17: =VLOOKUP(C17,'لیست پرسنل'!$A$1:$E$1004,4,FALSE) -> سرپرست آی تی | F17: =VLOOKUP(C17,'لیست پرسنل'!$A$1:$E$1004,2,FALSE) -> 2210 | G17: توسعه فولاد (362) | I17: دوربین مداربسته | J17: DAHUA DH-IPC-HFW2831TP-AS-S6 | K17: 9C0B450PAG3CF73 | L17: فاقد کد اموال
A18: AN362 | C18: آذر نیک اختر | D18: =VLOOKUP(C18,'لیست پرسنل'!$A$1:$E$1004,3,FALSE) -> فکورصنعت | E18: =VLOOKUP(C18,'لیست پرسنل'!$A$1:$E$1004,4,FALSE) -> سرپرست آی تی | F18: =VLOOKUP(C18,'لیست پرسنل'!$A$1:$E$1004,2,FALSE) -> 2210 | G18: توسعه فولاد (362) | I18: دوربین مداربسته | J18: DAHUA DH-IPC-HFW2831TP-AS-S7 | K18: 9C0B450PAG0419B | L18: فاقد کد اموال
A19: AN362 | C19: آذر نیک اختر | D19: =VLOOKUP(C19,'لیست پرسنل'!$A$1:$E$1004,3,FALSE) -> فکورصنعت | E19: =VLOOKUP(C19,'لیست پرسنل'!$A$1:$E$1004,4,FALSE) -> سرپرست آی تی | F19: =VLOOKUP(C19,'لیست پرسنل'!$A$1:$E$1004,2,FALSE) -> 2210 | G19: توسعه فولاد (362) | I19: دوربین مداربسته | J19: DAHUA DH-IPC-HFW2831TP-AS-S8 | K19: 9C0B450PAG33651 | L19: فاقد کد اموال
A20: AN362 | C20: آذر نیک اختر | D20: =VLOOKUP(C20,'لیست پرسنل'!$A$1:$E$1004,3,FALSE) -> فکورصنعت | E20: =VLOOKUP(C20,'لیست پرسنل'!$A$1:$E$1004,4,FALSE) -> سرپرست آی تی | F20: =VLOOKUP(C20,'لیست پرسنل'!$A$1:$E$1004,2,FALSE) -> 2210 | G20: توسعه فولاد (362) | I20: دوربین مداربسته | J20: DAHUA DH-IPC-HFW2831TP-AS-S9 | K20: 9C0B450PAG7DC41 | L20: فاقد کد اموال
A21: AN362 | C21: آذر نیک اختر | D21: =VLOOKUP(C21,'لیست پرسنل'!$A$1:$E$1004,3,FALSE) -> فکورصنعت | E21: =VLOOKUP(C21,'لیست پرسنل'!$A$1:$E$1004,4,FALSE) -> سرپرست آی تی | F21: =VLOOKUP(C21,'لیست پرسنل'!$A$1:$E$1004,2,FALSE) -> 2210 | G21: توسعه فولاد (362) | I21: دوربین مداربسته | J21: DAHUA DH-IPC-HFW3449EP-AS-LED | K21: 8A0424FPAG2C361 | L21: فاقد کد اموال | P21: جهت درخواست واحد پشتیبانی
A22: AN362 | C22: آذر نیک اختر | D22: =VLOOKUP(C22,'لیست پرسنل'!$A$1:$E$1004,3,FALSE) -> فکورصنعت | E22: =VLOOKUP(C22,'لیست پرسنل'!$A$1:$E$1004,4,FALSE) -> سرپرست آی تی | F22: =VLOOKUP(C22,'لیست پرسنل'!$A$1:$E$1004,2,FALSE) -> 2210 | G22: توسعه فولاد (362) | I22: دوربین مداربسته | J22: DAHUA DH-IPC-HFW3449EP-AS-LED | K22: 9F0104BPAG8CAB6 | L22: فاقد کد اموال | P22: جهت درخواست واحد پشتیبانی
A23: AN362 | C23: آذر نیک اختر | D23: =VLOOKUP(C23,'لیست پرسنل'!$A$1:$E$1004,3,FALSE) -> فکورصنعت | E23: =VLOOKUP(C23,'لیست پرسنل'!$A$1:$E$1004,4,FALSE) -> سرپرست آی تی | F23: =VLOOKUP(C23,'لیست پرسنل'!$A$1:$E$1004,2,FALSE) -> 2210 | G23: توسعه فولاد (362) | I23: دوربین مداربسته | J23: DAHUA DH-IPC-HFW3449EP-AS-LED | K23: 9F0104BPAGF0822 | L23: فاقد کد اموال | P23: جهت درخواست واحد پشتیبانی
A24: AN362 | C24: آذر نیک اختر | D24: =VLOOKUP(C24,'لیست پرسنل'!$A$1:$E$1004,3,FALSE) -> فکورصنعت | E24: =VLOOKUP(C24,'لیست پرسنل'!$A$1:$E$1004,4,FALSE) -> سرپرست آی تی | F24: =VLOOKUP(C24,'لیست پرسنل'!$A$1:$E$1004,2,FALSE) -> 2210 | G24: توسعه فولاد (362) | I24: دوربین مداربسته | J24: DAHUA DH-IPC-HFW3449EP-AS-LED | K24: 8A0424FPAGAC3EA | L24: فاقد کد اموال | P24: جهت درخواست واحد پشتیبانی
A25: AN362 | C25: آذر نیک اختر | D25: =VLOOKUP(C25,'لیست پرسنل'!$A$1:$E$1004,3,FALSE) -> فکورصنعت | E25: =VLOOKUP(C25,'لیست پرسنل'!$A$1:$E$1004,4,FALSE) -> سرپرست آی تی | F25: =VLOOKUP(C25,'لیست پرسنل'!$A$1:$E$1004,2,FALSE) -> 2210 | G25: توسعه فولاد (362) | I25: دوربین مداربسته | J25: DAHUA DH-IPC-HFW3449EP-AS-LED | K25: 9F0104BPAG30D6F | L25: فاقد کد اموال | P25: جهت درخواست واحد پشتیبانی
A26: AN362 | C26: آذر نیک اختر | D26: =VLOOKUP(C26,'لیست پرسنل'!$A$1:$E$1004,3,FALSE) -> فکورصنعت | E26: =VLOOKUP(C26,'لیست پرسنل'!$A$1:$E$1004,4,FALSE) -> سرپرست آی تی | F26: =VLOOKUP(C26,'لیست پرسنل'!$A$1:$E$1004,2,FALSE) -> 2210 | G26: توسعه فولاد (362) | I26: دوربین مداربسته | J26: DAHUA DH-IPC-HFW3449EP-AS-LED | K26: 9F0104BPAG301CF | L26: فاقد کد اموال | P26: جهت درخواست واحد پشتیبانی
A27: AN362 | C27: آذر نیک اختر | D27: =VLOOKUP(C27,'لیست پرسنل'!$A$1:$E$1004,3,FALSE) -> فکورصنعت | E27: =VLOOKUP(C27,'لیست پرسنل'!$A$1:$E$1004,4,FALSE) -> سرپرست آی تی | F27: =VLOOKUP(C27,'لیست پرسنل'!$A$1:$E$1004,2,FALSE) -> 2210 | G27: توسعه فولاد (362) | I27: دوربین مداربسته | J27: DAHUA DH-IPC-HFW3449EP-AS-LED | K27: 9F0104BPAG29168 | L27: فاقد کد اموال | P27: جهت درخواست واحد پشتیبانی
A28: AN362 | C28: آذر نیک اختر | D28: =VLOOKUP(C28,'لیست پرسنل'!$A$1:$E$1004,3,FALSE) -> فکورصنعت | E28: =VLOOKUP(C28,'لیست پرسنل'!$A$1:$E$1004,4,FALSE) -> سرپرست آی تی | F28: =VLOOKUP(C28,'لیست پرسنل'!$A$1:$E$1004,2,FALSE) -> 2210 | G28: توسعه فولاد (362) | I28: دوربین مداربسته | J28: DAHUA DH-IPC-HFW3449EP-AS-LED | K28: 9F0104BPAG35224 | L28: فاقد کد اموال | P28: جهت درخواست واحد پشتیبانی
A29: AN362 | C29: آذر نیک اختر | D29: =VLOOKUP(C29,'لیست پرسنل'!$A$1:$E$1004,3,FALSE) -> فکورصنعت | E29: =VLOOKUP(C29,'لیست پرسنل'!$A$1:$E$1004,4,FALSE) -> سرپرست آی تی | F29: =VLOOKUP(C29,'لیست پرسنل'!$A$1:$E$1004,2,FALSE) -> 2210 | G29: توسعه فولاد (362) | I29: دوربین مداربسته | J29: DAHUA DH-IPC-HFW3449EP-AS-LED | K29: 9F0104BPAGFCE6C | L29: فاقد کد اموال | P29: جهت درخواست واحد پشتیبانی
A30: AN362 | C30: آذر نیک اختر | D30: =VLOOKUP(C30,'لیست پرسنل'!$A$1:$E$1004,3,FALSE) -> فکورصنعت | E30: =VLOOKUP(C30,'لیست پرسنل'!$A$1:$E$1004,4,FALSE) -> سرپرست آی تی | F30: =VLOOKUP(C30,'لیست پرسنل'!$A$1:$E$1004,2,FALSE) -> 2210 | G30: توسعه فولاد (362) | I30: دوربین مداربسته | J30: DAHUA DH-IPC-HFW3449EP-AS-LED | K30: 9F0104BPAGAED75 | L30: فاقد کد اموال | P30: جهت درخواست واحد پشتیبانی
A31: AN362 | C31: آذر نیک اختر | D31: =VLOOKUP(C31,'لیست پرسنل'!$A$1:$E$1004,3,FALSE) -> فکورصنعت | E31: =VLOOKUP(C31,'لیست پرسنل'!$A$1:$E$1004,4,FALSE) -> سرپرست آی تی | F31: =VLOOKUP(C31,'لیست پرسنل'!$A$1:$E$1004,2,FALSE) -> 2210 | G31: انبار آی تی توسعه فولاد (362) | I31: دوربین مداربسته | J31: دوربین برند HIK VISION | L31: فاقد کد اموال | P31: ارسالی از سه چاهون
A32: AN362 | C32: آذر نیک اختر | D32: =VLOOKUP(C32,'لیست پرسنل'!$A$1:$E$1004,3,FALSE) -> فکورصنعت | E32: =VLOOKUP(C32,'لیست پرسنل'!$A$1:$E$1004,4,FALSE) -> سرپرست آی تی | F32: =VLOOKUP(C32,'لیست پرسنل'!$A$1:$E$1004,2,FALSE) -> 2210 | G32: انبار آی تی توسعه فولاد (362) | I32: دوربین مداربسته | J32: دوربین برند HIK VISION | L32: فاقد کد اموال | P32: ارسالی از سه چاهون
A33: AN362 | C33: آذر نیک اختر | D33: =VLOOKUP(C33,'لیست پرسنل'!$A$1:$E$1004,3,FALSE) -> فکورصنعت | E33: =VLOOKUP(C33,'لیست پرسنل'!$A$1:$E$1004,4,FALSE) -> سرپرست آی تی | F33: =VLOOKUP(C33,'لیست پرسنل'!$A$1:$E$1004,2,FALSE) -> 2210 | G33: انبار آی تی توسعه فولاد (362) | I33: دوربین | J33: دوربین برند TOPICA | L33: فاقد کد اموال | P33: ارسالی از سه چاهون
A34: AN362 | C34: آذر نیک اختر | D34: =VLOOKUP(C34,'لیست پرسنل'!$A$1:$E$1004,3,FALSE) -> فکورصنعت | E34: =VLOOKUP(C34,'لیست پرسنل'!$A$1:$E$1004,4,FALSE) -> سرپرست آی تی | F34: =VLOOKUP(C34,'لیست پرسنل'!$A$1:$E$1004,2,FALSE) -> 2210 | G34: انبار آی تی توسعه فولاد (362) | I34: دوربین مداربسته | J34: DAHUA DH-IPC-HDW2439 | K34: 7E05100PAG5F3E9 | L34: فاقد اموال | N34: خوابگاه دماوند سیرجان جمع اوری شد | P34: نصب در درب ورودی انبار
A35: AN390 | C35: کوروش افشین | D35: =VLOOKUP(C35,'لیست پرسنل'!$A$1:$E$1004,3,FALSE) -> فکورصنعت | E35: =VLOOKUP(C35,'لیست پرسنل'!$A$1:$E$1004,4,FALSE) -> انبار | F35: =VLOOKUP(C35,'لیست پرسنل'!$A$1:$E$1004,2,FALSE) -> 1536 | G35: انبار روباز گلفا (390) | I35: دوربین مداربسته | J35: دوربین مدار بسته | L35: فاقد کد اموال | P35: نصب شده در انبار رو باز گلفا 390
A36: AN390 | C36: کوروش افشین | D36: =VLOOKUP(C36,'لیست پرسنل'!$A$1:$E$1004,3,FALSE) -> فکورصنعت | E36: =VLOOKUP(C36,'لیست پرسنل'!$A$1:$E$1004,4,FALSE) -> انبار | F36: =VLOOKUP(C36,'لیست پرسنل'!$A$1:$E$1004,2,FALSE) -> 1536 | G36: انبار روباز گلفا (390) | I36: دوربین مداربسته | J36: دوربین مدار بسته | L36: فاقد کد اموال | P36: نصب شده در انبار رو باز گلفا 390
A37: AN390 | C37: کوروش افشین | D37: =VLOOKUP(C37,'لیست پرسنل'!$A$1:$E$1004,3,FALSE) -> فکورصنعت | E37: =VLOOKUP(C37,'لیست پرسنل'!$A$1:$E$1004,4,FALSE) -> انبار | F37: =VLOOKUP(C37,'لیست پرسنل'!$A$1:$E$1004,2,FALSE) -> 1536 | G37: انبار روباز گلفا (390) | I37: دوربین مداربسته | J37: دوربین مدار بسته | L37: فاقد کد اموال | P37: نصب شده در انبار رو باز گلفا 390
A38: AN390 | C38: کوروش افشین | D38: =VLOOKUP(C38,'لیست پرسنل'!$A$1:$E$1004,3,FALSE) -> فکورصنعت | E38: =VLOOKUP(C38,'لیست پرسنل'!$A$1:$E$1004,4,FALSE) -> انبار | F38: =VLOOKUP(C38,'لیست پرسنل'!$A$1:$E$1004,2,FALSE) -> 1536 | G38: انبار روباز گلفا (390) | I38: دوربین مداربسته | J38: دوربین مدار بسته | L38: فاقد کد اموال | P38: نصب شده در انبار رو باز گلفا 390
A39: AN390 | C39: کوروش افشین | D39: =VLOOKUP(C39,'لیست پرسنل'!$A$1:$E$1004,3,FALSE) -> فکورصنعت | E39: =VLOOKUP(C39,'لیست پرسنل'!$A$1:$E$1004,4,FALSE) -> انبار | F39: =VLOOKUP(C39,'لیست پرسنل'!$A$1:$E$1004,2,FALSE) -> 1536 | G39: انبار روباز گلفا (390) | I39: دوربین مداربسته | J39: دوربین مدار بسته | L39: فاقد کد اموال | P39: نصب شده در انبار رو باز گلفا 390
A40: AN392 | C40: آذر نیک اختر | D40: =VLOOKUP(C40,'لیست پرسنل'!$A$1:$E$1004,3,FALSE) -> فکورصنعت | E40: =VLOOKUP(C40,'لیست پرسنل'!$A$1:$E$1004,4,FALSE) -> سرپرست آی تی | F40: =VLOOKUP(C40,'لیست پرسنل'!$A$1:$E$1004,2,FALSE) -> 2210 | G40: انبار آی تی خرامه (392) | I40: دوربین مداربسته | J40: HIK VISION DS-2CD1023G0E-I | L40: فاقد کد اموال | P40: تحویل گرفته شده از شرکت ماشین سازی ویژه - متعلق به پروژه خرامه
...

Sheet ثبت نشده در سیما
A2: 461 | B2: سعید تالاری | C2: =VLOOKUP(B2,'لیست پرسنل'!$A$2:$D$1016,3,FALSE) -> فکورصنعت | D2: =VLOOKUP(B2,'لیست پرسنل'!$A$2:$D$1016,4,FALSE) -> مکانیک | E2: =VLOOKUP(B2,'لیست پرسنل'!$A$2:$E$1016,2,FALSE) -> 0 | F2: فولاد بردسیر (461) | G2: BS53C74 | H2: تلفن سیسکو | I2: Cisco CP-6941 | J2: PUC17430JQM | K2: 633735
A3: 461 | B3: سعید تالاری | C3: =VLOOKUP(B3,'لیست پرسنل'!$A$2:$D$1016,3,FALSE) -> فکورصنعت | D3: =VLOOKUP(B3,'لیست پرسنل'!$A$2:$D$1016,4,FALSE) -> مکانیک | E3: =VLOOKUP(B3,'لیست پرسنل'!$A$2:$E$1016,2,FALSE) -> 0 | F3: فولاد بردسیر (461) | G3: BS53C74 | H3: کیس | I3: کیس گرین B660 | K3: 635098
A4: 461 | B4: سعید تالاری | C4: =VLOOKUP(B4,'لیست پرسنل'!$A$2:$D$1016,3,FALSE) -> فکورصنعت | D4: =VLOOKUP(B4,'لیست پرسنل'!$A$2:$D$1016,4,FALSE) -> مکانیک | E4: =VLOOKUP(B4,'لیست پرسنل'!$A$2:$E$1016,2,FALSE) -> 0 | F4: فولاد بردسیر (461) | G4: BS53C74 | H4: مانيتور | I4: Lenovo 22" L22i-30 | J4: U563BKK1 | K4: 626460

Sheet لیست تعمیرات
A1: قطعات ارسال شده به تهران جهت تعمیر
A2: نوع قطعه | B2: مدل | C2: شماره سریال | D2: کد اموال | E2: توضیحات | F2: وضعیت | G2: محل اسقرار
A3: Monitor | B3: LG W2261VP | C3: 722003-009032981 | D3: 605441 | E3: تعمیر تهران - - از تعمیر برگشت | F3: از تعمیر برگشت
A4: Monitor | B4: LG 22” FLAT W2262TQ | C4: 686004-012063470 | D4: 611436 | E4: تعمیر تهران - ارسال جهت تعمیر - مربوط به ایزدی کارفرما خرامه | F4: ؟
A5: Video Projector | B5: Optima Projector EX 540i | C5: Q8FR111AAAAAC0015 | D5: 606814 | E5: تعمیر تهران - ارسال جهت تعمیر - برگشت از تعمیر | F5: از تعمیر برگشت
A6: Monitor | B6: LG22" LED 22MP55HQ | C6: 402NDCRFR059 | D6: 609604 | E6: مانیتور رضا کاظمی ارسال جهت تعمیر به تهران | F6: از تعمیر برگشت
A7: Monitor | B7: LG 22" W2261VP | C7: 722006012072875 | D7: 603251 | E7: مانیتور جدیدالاسلام ارسال جهت تعمیر به تهران-از تعمیر برگشت | F7: از تعمیر برگشت
A8: Monitor | B8: LG 22" LCD W2262TQ | C8: 0686003 - 011060033 | D8: 613925 | E8: مانیتور مخلصی ارسال جهت تعمیر به تهران-از تعمیر برگشت | F8: از تعمیر برگشت
A9: Clock card | B9: دستگاه کارت ساعت زنی iFace 202 | C9: 607715-2800156 | D9: 613144 | E9: دستگاه کارت ساعت زنی توسعه ارسال جهت تعمیر-برگشت از تعمیرات | F9: از تعمیر برگشت
A10: Switch | B10: یک دستگاه سوییچ 48 پورت CISCO مدلPOE 3750 | C10: CAT0932N45H | D10: 623228 | E10: ارسال جهت تعمیر - از تعمیر برگشت | F10: از تعمیر برگشت
A11: Clock card | B11: دستگاه کارت ساعت پلیکام | D11: 612105 | E11: خرابی چشم دستگاه و نشناختن چهره - برگشت از تعمیر | F11: از تعمیر برگشت
A12: Monitor | B12: LG 22" W2261VP | C12: 722003009033183 | D12: 603305 | E12: ایمان پاسواری - روشن نشدن - از تعمیر برگشت | F12: از تعمیر برگشت
A13: Monitor | B13: LG 22" W2261VP | C13: 0722009105031153 | D13: 603356 | E13: سعید دارابی خرامه - ازتعمیر برگشت | F13: از تعمیر برگشت
A14: Monitor | B14: LG 22" W2261VP | C14: 0722006-012072824 | D14: 600764 | E14: محمد رضا طباطبایی پروژه فولاد | F14: از تعمیر برگشت
A15: Monitor | B15: LG 22" W2261VP | C15: 0686002011058231 | D15: 604093 | E15: ابوالفضل غلامی - ارسال جهت تعمیر-از تعمیر برگشت | F15: از تعمیر برگشت
A16: Monitor | B16: LG 19" W1953SE | C16: 0698016 - 205025191 | D16: 603936 | E16: مانیتور سرور نظارت کارفرما - دهنوی-از تعمیر برگشت | F16: از تعمیر برگشت
A17: Monitor | B17: LG 22" W2261VP | C17: 072200107046186 | D17: 609609 | E17: فرشاد سلیمانی (واحد مکانیک ) -ارسال به تعمیر-از تعمیر برگشت | F17: از تعمیر برگشت
A18: Monitor | B18: LG 22" W2262TQ | C18: 666003011059242 | D18: 608004 | E18: ارسال جهت تعمیر - امین خراسانی ( سیویل ) پروژه سایت مرکز تحقیقات | F18: از تعمیر برگشت
A19: جدید
B20: LG 22" W2262TQ | C20: 0686004012063472 | D20: 604975 | E20: مانیتور محمد باجلان کارفرما سایت توسعه فولاد به علت روشن نشدن | F20: در تاریخ 18/11/1401 از تعمیر برگشت
B21: LG 22" MP55HQ | C21: 403NDMTJM211 | D21: 609605 | E21: موجودی انبار سایت توسعه فولاد به علت خط داشتن تصویر | F21: در تاریخ 06/12/1401 از تعمیر برگشت
B22: LG 22" W2261VP | C22: 0722001007047601 | D22: 604092 | E22: مانیتور جابر زیدآبادی نژاد-مرکز تحقیقات-علت روشن نشدن | F22: در تاریخ 1401/12/10 از تعمیر برگشت
B23: LG 22" W2261VP | C23: 0722007101006229 | D23: 601031 | E23: ارسال به تعمیر به علت مات بودن تصویر - مانیتور قبلی آرمان فرخ | F23: در تاریخ 06/12/1401 از تعمیر برگشت
B24: Canon MF3010 | C24: WEP55093 | D24: 623630 | E24: جهت تعمیر تحویل سروش کریمی شده | F24: در تاریخ 1402/01/20 از تعمیر برگشت
B25: LG 22" W2261VP | C25: 722015205013365 | D25: 603171 | E25: مانیتور قبلی کاظم زلفی - روشن نمیشود | F25: در تاریخ 1401/12/20 از تعمیر برگشت
B26: LG 22" 22MP55HQ | C26: 402NDPHFR824 | D26: 610923 | E26: داشتن خط هنگام روشن شدن صفحه نمایش | F26: در تاریخ 1402/02/05 از تعمیر برگشت
B27: LG 22" 22MP55HQ | C27: 404NDJXEA980 | D27: 611437 | E27: داشتن خط هنگام روشن شدن صفحه نمایش | F27: در تاریخ 1402/01/29 از تعمیر برگشت
B28: LG 22" W2262TQ | C28: 0686003011060029 | D28: 603562 | E28: به علت روشن نشدن -مانتیور قبلی مسلمی | F28: در تاریخ 1402/01/29 از تعمیر برگشت
B29: LG 19" W1953SE | C29: 0698014204006918 | D29: 601557 | E29: علت خاموش روشن شدن تصویر -تحویلی از آی کپس | F29: در تاریخ 1402/01/29 از تعمیر برگشت
B30: CISCO 6941 | C30: PUC17430HJA | D30: 628828 | E30: به علت داخلی نگرفتن -تلفن قبلی اکبری | F30: در تاریخ 1402/01/29 از تعمیر برگشت
B31: CISCO 6941 | C31: PXN1527V5U0 | D31: 628859 | E31: روشن نشدن مانیتور -آبدارخانه بردسیر | F31: در تاریخ 1402/01/29 از تعمیر برگشت
B32: Optoma Projector EX 540i | C32: Q8FR111AAAAAC0015 | D32: 606814 | E32: به علت روشن نشدن لامپ تصویر -کانکس آموزش ایمنی | F32: در تاریخ 1402/02/05 از تعمیر برگشت
B33: LG 22" W2261VP | C33: 0722010109000299 | D33: 604289 | E33: ه علت روشن نشدن تحویلی از آقای میلاد صفی جهانشاهی کارفرما سایت توسعه فولاد | F33: در تاریخ 1402/01/29 از تعمیر برگشت
B34: Samsung 19" 1931 | C34: BF.H9MN6.011449 | D34: 605715 | E34: به علت روشن نشدن موجودی انبار سایت توسعه فولاد | F34: در تاریخ 1402/01/29 از تعمیر برگشت
B35: HP Laser Jet P2035 | C35: VNC3565042 | D35: 610516 | E35: مشکل در پرینت . پرینتر آقای شعشعانی | F35: در تاریخ 1402/01/27 از تعمیر برگشت
B36: LG 22" 22M38H | C36: 0175002910009954 | D36: 618922 | E36: به علت شکستگی پایین تصویر -مانتیور پیام مرادی بردسیر | F36: در تاریخ 1402/02/11 از تعمیر برگشت
B37: SAMSUNG -SL-M2070F | C37: 073EB8KH9D00T2R | D37: 611811 | E37: به علت خرابی فیوزینگ -پرینتر سوپروایزر - تحویل سروش کریمی شد | F37: در تاریخ 1402/02/06 از تعمیر برگشت
A38: Monitor | B38: LG 22" W2261VP | C38: 0722006012072875 | D38: 603251 | E38: به علت روشن نشدن مانیتور جدیدالاسلام-برای بار دوم به تعمیر ارسال شد | F38: در تاریخ 1402/02/11 از تعمیر برگشت
B39: HP LaserJet 1320 | C39: 55034848 | D39: 607358 | E39: پرینتر کیوان - تحویل کریمی شد بابت تعمیر | F39: در تاریخ 1402/02/07 از تعمیر برگشت
B40: LG 22" W2262TQ | C40: 0686004012063391 | D40: 607686 | E40: علت تعمییر خاموش شدن ناگهانی | F40: در تاریخ 1402/03/10 از تعمیر برگشت
...

Sheet اموال قبلا چک شده بنام نیک اختر
A1: ردیف | B1: شماره پلاك | C1: شرح پلاك | D1: محل استقرار | E1: مشخصات فنی | F1: تحویل گیرنده 1 | G1: تاریخ اختتام | H1: علت اختتام | I1: تاريخ خريد
A2: 1 | B2: 200056 | C2: كانكس 12 متري مان | D2: (362) پروژه احداث كارخانه فولاد گل گهر | E2: دو اتاقه - IT | F2: آذر نيك اختر | G2: 0 | I2: 13910403
A3: 2 | B3: 200066 | C3: كانكس 6 متري ماهان | D3: (110) پروژه گوهر زمين | E3: تك اتاقه - IT | F3: آذر نيك اختر | G3: 0 | I3: 13911228
A4: 406 | B4: 613862 | C4: صندلي نيلپر K 600 | D4: (110) پروژه گوهر زمين | F4: آذر نيك اختر | G4: 0 | I4: 13950929
A5: 412 | B5: 614023 | C5: كولر گازي پنجره اي 18000 O GENERAL | D5: (110) پروژه گوهر زمين | F5: آذر نيك اختر | G5: 0 | I5: 13951105
A6: 413 | B6: 614042 | C6: كولر اسپيلت سردو گرمSAMSUNG 18000 | D6: (110) پروژه گوهر زمين | F6: آذر نيك اختر | G6: 0 | I6: 13951105

Sheet مختوم شده
A2: کد پروژه | B2: محل | C2: ردیف | D2: تحویل گیرنده اول | E2: شرکت | F2: واحد | G2: کد پرسنلی | H2: محل استقرار | I2: کد شناسایی سیستم | J2: گروه بندی | K2: مدل | L2: سریال | M2: کد اموال | N2: تحویل گیرنده دوم | O2: تحویل گیرنده -1 | P2: تحویل گیرنده -2 | Q2: توضیحات | R2: مختوم شده | S2: تاریخ اختتام
A3: بهاباد یزد | B3: C17 | C3: 10 | D3: احسان موسوی | E3: =VLOOKUP(D3,'لیست پرسنل'!$A$2:$D$1016,3,FALSE) -> كنسانتره سنگ آهن بهاباد يزد | F3: =VLOOKUP(D3,'لیست پرسنل'!$A$2:$D$1016,4,FALSE) -> مدیر سایت | G3: =VLOOKUP(D3,'لیست پرسنل'!$A$2:$E$1016,2,FALSE) -> 0 | H3: كنسانتره سنگ آهن بهاباد يزد | I3: CH10C17 | J3: مانيتور | K3: LG 22" 22MP55 | L3: 402NDTCFR017 | M3: 609607 | O3: بازیافت باطله چادرملو (159) | R3: به کارفرما فروخته شد | S3: 1404/06/11
A4: بهاباد یزد | B4: C17 | C4: 9 | D4: سجاد اشرفی | E4: =VLOOKUP(D4,'لیست پرسنل'!$A$2:$D$1016,3,FALSE) -> كنسانتره سنگ آهن بهاباد يزد | F4: =VLOOKUP(D4,'لیست پرسنل'!$A$2:$D$1016,4,FALSE) -> 0 | G4: =VLOOKUP(D4,'لیست پرسنل'!$A$2:$E$1016,2,FALSE) -> 0 | H4: كنسانتره سنگ آهن بهاباد يزد | I4: CH9C17 | J4: مانيتور | K4: LG 22" 22MP55 | L4: 402NDHBFR009 | M4: 610930 | O4: بازیافت باطله چادرملو (159) | R4: به کارفرما فروخته شد | S4: 1404/06/11
A5: بهاباد یزد | B5: C17 | C5: 10 | D5: احسان موسوی | E5: =VLOOKUP(D5,'لیست پرسنل'!$A$2:$D$1016,3,FALSE) -> كنسانتره سنگ آهن بهاباد يزد | F5: =VLOOKUP(D5,'لیست پرسنل'!$A$2:$D$1016,4,FALSE) -> مدیر سایت | G5: =VLOOKUP(D5,'لیست پرسنل'!$A$2:$E$1016,2,FALSE) -> 0 | H5: كنسانتره سنگ آهن بهاباد يزد | I5: CH10C17 | J5: کیس | K5: i7 | M5: 619925 | O5: بازیافت باطله چادرملو (159) | R5: به کارفرما فروخته شد | S5: 1404/06/11
A6: بهاباد يزد | B6: بهاباد يزد | D6: حسین عبدشاهی | E6: =VLOOKUP(D6,'لیست پرسنل'!$A$2:$D$1016,3,FALSE) -> فکورصنعت | F6: =VLOOKUP(D6,'لیست پرسنل'!$A$2:$D$1016,4,FALSE) -> تحقیق و توسعه فکور | G6: =VLOOKUP(D6,'لیست پرسنل'!$A$2:$E$1016,2,FALSE) -> 0 | H6: كنسانتره سنگ آهن بهاباد يزد | J6: مانيتور | K6: Monitor Gplus 245 JN | M6: 623983 | N6: مهندس عنایتی فر (روناک) | R6: به کارفرما فروخته شد | S6: 1404/06/11
A7: بهاباد يزد | B7: بهاباد يزد | D7: حسین عبدشاهی | E7: =VLOOKUP(D7,'لیست پرسنل'!$A$2:$D$1016,3,FALSE) -> فکورصنعت | F7: =VLOOKUP(D7,'لیست پرسنل'!$A$2:$D$1016,4,FALSE) -> تحقیق و توسعه فکور | G7: =VLOOKUP(D7,'لیست پرسنل'!$A$2:$E$1016,2,FALSE) -> 0 | H7: كنسانتره سنگ آهن بهاباد يزد | J7: مانيتور | K7: Monitor Gplus 245 JN | M7: 623984 | N7: مهندس رجبی (روناک) | R7: به کارفرما فروخته شد | S7: 1404/06/11
A8: بهاباد يزد | B8: بهاباد يزد | D8: حسین عبدشاهی | E8: =VLOOKUP(D8,'لیست پرسنل'!$A$2:$D$1016,3,FALSE) -> فکورصنعت | F8: =VLOOKUP(D8,'لیست پرسنل'!$A$2:$D$1016,4,FALSE) -> تحقیق و توسعه فکور | G8: =VLOOKUP(D8,'لیست پرسنل'!$A$2:$E$1016,2,FALSE) -> 0 | H8: كنسانتره سنگ آهن بهاباد يزد | J8: مانيتور | K8: Monitor Gplus 245 JN | M8: 623985 | N8: مهندس عباسلو (روناک) | R8: به کارفرما فروخته شد | S8: 1404/06/11
A9: بهاباد يزد | B9: بهاباد يزد | D9: حسین عبدشاهی | E9: =VLOOKUP(D9,'لیست پرسنل'!$A$2:$D$1016,3,FALSE) -> فکورصنعت | F9: =VLOOKUP(D9,'لیست پرسنل'!$A$2:$D$1016,4,FALSE) -> تحقیق و توسعه فکور | G9: =VLOOKUP(D9,'لیست پرسنل'!$A$2:$E$1016,2,FALSE) -> 0 | H9: كنسانتره سنگ آهن بهاباد يزد | J9: مانيتور | K9: Monitor Gplus 245 JN | M9: 623986 | N9: مهندس بهروز به نژاد (روناک) | R9: به کارفرما فروخته شد | S9: 1404/06/11
A10: بهاباد يزد | B10: بهاباد يزد | D10: حسین عبدشاهی | E10: =VLOOKUP(D10,'لیست پرسنل'!$A$2:$D$1016,3,FALSE) -> فکورصنعت | F10: =VLOOKUP(D10,'لیست پرسنل'!$A$2:$D$1016,4,FALSE) -> تحقیق و توسعه فکور | G10: =VLOOKUP(D10,'لیست پرسنل'!$A$2:$E$1016,2,FALSE) -> 0 | H10: كنسانتره سنگ آهن بهاباد يزد | J10: پرینتر | K10: Printer 3 كاره CANON | M10: 624030 | N10: مهندس بهروز به نژاد (روناک) | R10: به کارفرما فروخته شد | S10: 1404/06/11
A11: بهاباد يزد | B11: بهاباد يزد | D11: حسین عبدشاهی | E11: =VLOOKUP(D11,'لیست پرسنل'!$A$2:$D$1016,3,FALSE) -> فکورصنعت | F11: =VLOOKUP(D11,'لیست پرسنل'!$A$2:$D$1016,4,FALSE) -> تحقیق و توسعه فکور | G11: =VLOOKUP(D11,'لیست پرسنل'!$A$2:$E$1016,2,FALSE) -> 0 | H11: كنسانتره سنگ آهن بهاباد يزد | J11: تلويزيون | K11: TV Daewoo DLE | M11: 624033 | N11: خوابگاه کارشناسی روناک | R11: به کارفرما فروخته شد | S11: 1404/06/11
A12: بهاباد یزد | B12: C17 | C12: 9 | D12: سجاد اشرفی | E12: =VLOOKUP(D12,'لیست پرسنل'!$A$2:$D$1016,3,FALSE) -> كنسانتره سنگ آهن بهاباد يزد | F12: =VLOOKUP(D12,'لیست پرسنل'!$A$2:$D$1016,4,FALSE) -> 0 | G12: =VLOOKUP(D12,'لیست پرسنل'!$A$2:$E$1016,2,FALSE) -> 0 | H12: كنسانتره سنگ آهن بهاباد يزد | I12: CH9C17 | J12: کیس | M12: 624719 | O12: بازیافت باطله چادرملو (159) | R12: به کارفرما فروخته شد | S12: 1404/06/11
A13: بهاباد يزد | B13: بهاباد يزد | D13: حسین عبدشاهی | E13: =VLOOKUP(D13,'لیست پرسنل'!$A$2:$D$1016,3,FALSE) -> فکورصنعت | F13: =VLOOKUP(D13,'لیست پرسنل'!$A$2:$D$1016,4,FALSE) -> تحقیق و توسعه فکور | G13: =VLOOKUP(D13,'لیست پرسنل'!$A$2:$E$1016,2,FALSE) -> 0 | H13: كنسانتره سنگ آهن بهاباد يزد | J13: مانيتور | K13: Monitor GPLUS GDM | M13: 624777 | N13: اداری روناک | R13: به کارفرما فروخته شد | S13: 1404/06/11
A14: بهاباد يزد | B14: بهاباد يزد | D14: حسین عبدشاهی | E14: =VLOOKUP(D14,'لیست پرسنل'!$A$2:$D$1016,3,FALSE) -> فکورصنعت | F14: =VLOOKUP(D14,'لیست پرسنل'!$A$2:$D$1016,4,FALSE) -> تحقیق و توسعه فکور | G14: =VLOOKUP(D14,'لیست پرسنل'!$A$2:$E$1016,2,FALSE) -> 0 | H14: كنسانتره سنگ آهن بهاباد يزد | J14: مانيتور | K14: Monitor GPLUS GDM | M14: 624778 | N14: اداری روناک | R14: به کارفرما فروخته شد | S14: 1404/06/11
A15: بهاباد يزد | B15: بهاباد يزد | D15: حسین عبدشاهی | E15: =VLOOKUP(D15,'لیست پرسنل'!$A$2:$D$1016,3,FALSE) -> فکورصنعت | F15: =VLOOKUP(D15,'لیست پرسنل'!$A$2:$D$1016,4,FALSE) -> تحقیق و توسعه فکور | G15: =VLOOKUP(D15,'لیست پرسنل'!$A$2:$E$1016,2,FALSE) -> 0 | H15: كنسانتره سنگ آهن بهاباد يزد | J15: پرینتر | K15: Printer Canon 3010 | M15: 624779 | N15: امیدزینلی (روناک) | R15: به کارفرما فروخته شد | S15: 1404/06/11
A16: بهاباد يزد | B16: بهاباد يزد | D16: حسین عبدشاهی | E16: =VLOOKUP(D16,'لیست پرسنل'!$A$2:$D$1016,3,FALSE) -> فکورصنعت | F16: =VLOOKUP(D16,'لیست پرسنل'!$A$2:$D$1016,4,FALSE) -> تحقیق و توسعه فکور | G16: =VLOOKUP(D16,'لیست پرسنل'!$A$2:$E$1016,2,FALSE) -> 0 | H16: كنسانتره سنگ آهن بهاباد يزد | J16: پرینتر | K16: Printer Canon 3010 | M16: 624780 | N16: مهندس صالحی راد (روناک) | R16: به کارفرما فروخته شد | S16: 1404/06/11
A17: بهاباد يزد | B17: بهاباد يزد | D17: حسین عبدشاهی | E17: =VLOOKUP(D17,'لیست پرسنل'!$A$2:$D$1016,3,FALSE) -> فکورصنعت | F17: =VLOOKUP(D17,'لیست پرسنل'!$A$2:$D$1016,4,FALSE) -> تحقیق و توسعه فکور | G17: =VLOOKUP(D17,'لیست پرسنل'!$A$2:$E$1016,2,FALSE) -> 0 | H17: كنسانتره سنگ آهن بهاباد يزد | J17: پرینتر | K17: HP LaserJet MFP M436dn | M17: 624781 | N17: مهندس عباسلو (روناک) | R17: به کارفرما فروخته شد | S17: 1404/06/11
A18: بهاباد يزد | B18: بهاباد يزد | D18: حسین عبدشاهی | E18: =VLOOKUP(D18,'لیست پرسنل'!$A$2:$D$1016,3,FALSE) -> فکورصنعت | F18: =VLOOKUP(D18,'لیست پرسنل'!$A$2:$D$1016,4,FALSE) -> تحقیق و توسعه فکور | G18: =VLOOKUP(D18,'لیست پرسنل'!$A$2:$E$1016,2,FALSE) -> 0 | H18: كنسانتره سنگ آهن بهاباد يزد | J18: تلويزيون | K18: TV 65" LED Snowa SSD-65SA6 20U | M18: 625002 | N18: دفاتر اداری عصرنوین | R18: به کارفرما فروخته شد | S18: 1404/06/11
A19: بهاباد یزد | B19: C17 | C19: 9 | D19: سجاد اشرفی | E19: =VLOOKUP(D19,'لیست پرسنل'!$A$2:$D$1016,3,FALSE) -> كنسانتره سنگ آهن بهاباد يزد | F19: =VLOOKUP(D19,'لیست پرسنل'!$A$2:$D$1016,4,FALSE) -> 0 | G19: =VLOOKUP(D19,'لیست پرسنل'!$A$2:$E$1016,2,FALSE) -> 0 | H19: كنسانتره سنگ آهن بهاباد يزد | I19: CH9C17 | J19: پرینتر | K19: HP M428 | L19: CNDRP4WB5P | M19: 624923 | O19: بازیافت باطله چادرملو (159) | R19: به کارفرما فروخته شد | S19: 1404/06/11
A20: بهاباد يزد | B20: بهاباد يزد | D20: حسین عبدشاهی | E20: =VLOOKUP(D20,'لیست پرسنل'!$A$2:$D$1016,3,FALSE) -> فکورصنعت | F20: =VLOOKUP(D20,'لیست پرسنل'!$A$2:$D$1016,4,FALSE) -> تحقیق و توسعه فکور | G20: =VLOOKUP(D20,'لیست پرسنل'!$A$2:$E$1016,2,FALSE) -> 0 | H20: كنسانتره سنگ آهن بهاباد يزد | J20: تلويزيون | K20: TV Daewoo LED 43" | M20: 625266 | N20: خوابگاه مهندس اشرفی(عصرنوین) | R20: به کارفرما فروخته شد | S20: 1404/06/11
A21: بهاباد يزد | B21: بهاباد يزد | D21: حسین عبدشاهی | E21: =VLOOKUP(D21,'لیست پرسنل'!$A$2:$D$1016,3,FALSE) -> فکورصنعت | F21: =VLOOKUP(D21,'لیست پرسنل'!$A$2:$D$1016,4,FALSE) -> تحقیق و توسعه فکور | G21: =VLOOKUP(D21,'لیست پرسنل'!$A$2:$E$1016,2,FALSE) -> 0 | H21: كنسانتره سنگ آهن بهاباد يزد | J21: تلويزيون | K21: TV Daewoo LED 43" | M21: 625267 | N21: خوابگاه مهندس به نیا (پامیدکو) | R21: به کارفرما فروخته شد | S21: 1404/06/11
A22: بهاباد يزد | B22: بهاباد يزد | D22: حسین عبدشاهی | E22: =VLOOKUP(D22,'لیست پرسنل'!$A$2:$D$1016,3,FALSE) -> فکورصنعت | F22: =VLOOKUP(D22,'لیست پرسنل'!$A$2:$D$1016,4,FALSE) -> تحقیق و توسعه فکور | G22: =VLOOKUP(D22,'لیست پرسنل'!$A$2:$E$1016,2,FALSE) -> 0 | H22: كنسانتره سنگ آهن بهاباد يزد | J22: تلويزيون | K22: TV Daewoo LED 43" | M22: 625268 | N22: خوابگاه مهندس زاهدی(عصرنوین) | R22: به کارفرما فروخته شد | S22: 1404/06/11
A23: بهاباد يزد | B23: بهاباد يزد | D23: حسین عبدشاهی | E23: =VLOOKUP(D23,'لیست پرسنل'!$A$2:$D$1016,3,FALSE) -> فکورصنعت | F23: =VLOOKUP(D23,'لیست پرسنل'!$A$2:$D$1016,4,FALSE) -> تحقیق و توسعه فکور | G23: =VLOOKUP(D23,'لیست پرسنل'!$A$2:$E$1016,2,FALSE) -> 0 | H23: كنسانتره سنگ آهن بهاباد يزد | J23: تلويزيون | K23: TV Daewoo LED 43" | M23: 625269 | N23: خوابگاه مهندس موسوی (عصرنوین) | R23: به کارفرما فروخته شد | S23: 1404/06/11
A24: بهاباد يزد | B24: بهاباد يزد | D24: حسین عبدشاهی | E24: =VLOOKUP(D24,'لیست پرسنل'!$A$2:$D$1016,3,FALSE) -> فکورصنعت | F24: =VLOOKUP(D24,'لیست پرسنل'!$A$2:$D$1016,4,FALSE) -> تحقیق و توسعه فکور | G24: =VLOOKUP(D24,'لیست پرسنل'!$A$2:$E$1016,2,FALSE) -> 0 | H24: كنسانتره سنگ آهن بهاباد يزد | J24: مانيتور | K24: مانيتور جي پلاس 24 | M24: 628155 | Q24: نصب در (اداری عصر نوین) | R24: به کارفرما فروخته شد | S24: 1404/06/11
A25: بهاباد يزد | B25: بهاباد يزد | D25: حسین عبدشاهی | E25: =VLOOKUP(D25,'لیست پرسنل'!$A$2:$D$1016,3,FALSE) -> فکورصنعت | F25: =VLOOKUP(D25,'لیست پرسنل'!$A$2:$D$1016,4,FALSE) -> تحقیق و توسعه فکور | G25: =VLOOKUP(D25,'لیست پرسنل'!$A$2:$E$1016,2,FALSE) -> 0 | H25: كنسانتره سنگ آهن بهاباد يزد | J25: مانيتور | K25: مانیتور جی پلاس 24 | M25: 628156 | R25: به کارفرما فروخته شد | S25: 1404/06/11
A26: بهاباد يزد | B26: بهاباد يزد | D26: حسین عبدشاهی | E26: =VLOOKUP(D26,'لیست پرسنل'!$A$2:$D$1016,3,FALSE) -> فکورصنعت | F26: =VLOOKUP(D26,'لیست پرسنل'!$A$2:$D$1016,4,FALSE) -> تحقیق و توسعه فکور | G26: =VLOOKUP(D26,'لیست پرسنل'!$A$2:$E$1016,2,FALSE) -> 0 | H26: كنسانتره سنگ آهن بهاباد يزد | J26: مانيتور | K26: مانيتور جي پلاس 24 | M26: 628157 | Q26: نصب در (اداری عصر نوین) | R26: به کارفرما فروخته شد | S26: 1404/06/11
A27: بهاباد يزد | B27: بهاباد يزد | D27: حسین عبدشاهی | E27: =VLOOKUP(D27,'لیست پرسنل'!$A$2:$D$1016,3,FALSE) -> فکورصنعت | F27: =VLOOKUP(D27,'لیست پرسنل'!$A$2:$D$1016,4,FALSE) -> تحقیق و توسعه فکور | G27: =VLOOKUP(D27,'لیست پرسنل'!$A$2:$E$1016,2,FALSE) -> 0 | H27: كنسانتره سنگ آهن بهاباد يزد | J27: پرینتر | K27: پرینتر 3 کاره canon مدل 3010 | M27: 628994 | R27: به کارفرما فروخته شد | S27: 1404/06/11
A28: بهاباد يزد | B28: بهاباد يزد | D28: حسین عبدشاهی | E28: =VLOOKUP(D28,'لیست پرسنل'!$A$2:$D$1016,3,FALSE) -> فکورصنعت | F28: =VLOOKUP(D28,'لیست پرسنل'!$A$2:$D$1016,4,FALSE) -> تحقیق و توسعه فکور | G28: =VLOOKUP(D28,'لیست پرسنل'!$A$2:$E$1016,2,FALSE) -> 0 | H28: كنسانتره سنگ آهن بهاباد يزد | J28: تلفن Voip | K28: گوشی تلفن تحت شبکه گرند استریم | M28: 629325 | R28: به کارفرما فروخته شد | S28: 1404/06/11
A29: بهاباد يزد | B29: بهاباد يزد | D29: حسین عبدشاهی | E29: =VLOOKUP(D29,'لیست پرسنل'!$A$2:$D$1016,3,FALSE) -> فکورصنعت | F29: =VLOOKUP(D29,'لیست پرسنل'!$A$2:$D$1016,4,FALSE) -> تحقیق و توسعه فکور | G29: =VLOOKUP(D29,'لیست پرسنل'!$A$2:$E$1016,2,FALSE) -> 0 | H29: كنسانتره سنگ آهن بهاباد يزد | J29: تلفن Voip | K29: گوشی تلفن تحت شبکه گرند استریم | M29: 629326 | R29: به کارفرما فروخته شد | S29: 1404/06/11
A30: بهاباد يزد | B30: بهاباد يزد | D30: حسین عبدشاهی | E30: =VLOOKUP(D30,'لیست پرسنل'!$A$2:$D$1016,3,FALSE) -> فکورصنعت | F30: =VLOOKUP(D30,'لیست پرسنل'!$A$2:$D$1016,4,FALSE) -> تحقیق و توسعه فکور | G30: =VLOOKUP(D30,'لیست پرسنل'!$A$2:$E$1016,2,FALSE) -> 0 | H30: كنسانتره سنگ آهن بهاباد يزد | J30: تلفن Voip | K30: گوشی تلفن تحت شبکه گرند استریم | M30: 629327 | R30: به کارفرما فروخته شد | S30: 1404/06/11
A31: بهاباد يزد | B31: بهاباد يزد | D31: حسین عبدشاهی | E31: =VLOOKUP(D31,'لیست پرسنل'!$A$2:$D$1016,3,FALSE) -> فکورصنعت | F31: =VLOOKUP(D31,'لیست پرسنل'!$A$2:$D$1016,4,FALSE) -> تحقیق و توسعه فکور | G31: =VLOOKUP(D31,'لیست پرسنل'!$A$2:$E$1016,2,FALSE) -> 0 | H31: كنسانتره سنگ آهن بهاباد يزد | J31: تلفن Voip | K31: گوشی تلفن تحت شبکه گرند استریم | M31: 629328 | R31: به کارفرما فروخته شد | S31: 1404/06/11
A32: بهاباد يزد | B32: بهاباد يزد | D32: حسین عبدشاهی | E32: =VLOOKUP(D32,'لیست پرسنل'!$A$2:$D$1016,3,FALSE) -> فکورصنعت | F32: =VLOOKUP(D32,'لیست پرسنل'!$A$2:$D$1016,4,FALSE) -> تحقیق و توسعه فکور | G32: =VLOOKUP(D32,'لیست پرسنل'!$A$2:$E$1016,2,FALSE) -> 0 | H32: كنسانتره سنگ آهن بهاباد يزد | J32: تلفن Voip | K32: گوشی تلفن تحت شبکه گرند استریم | M32: 629329 | R32: به کارفرما فروخته شد | S32: 1404/06/11
A33: بهاباد يزد | B33: بهاباد يزد | D33: حسین عبدشاهی | E33: =VLOOKUP(D33,'لیست پرسنل'!$A$2:$D$1016,3,FALSE) -> فکورصنعت | F33: =VLOOKUP(D33,'لیست پرسنل'!$A$2:$D$1016,4,FALSE) -> تحقیق و توسعه فکور | G33: =VLOOKUP(D33,'لیست پرسنل'!$A$2:$E$1016,2,FALSE) -> 0 | H33: كنسانتره سنگ آهن بهاباد يزد | J33: مانيتور | K33: مانیتور جی پلاس 24-5JN | M33: 629331 | R33: به کارفرما فروخته شد | S33: 1404/06/11
A34: بهاباد يزد | B34: بهاباد يزد | D34: حسین عبدشاهی | E34: =VLOOKUP(D34,'لیست پرسنل'!$A$2:$D$1016,3,FALSE) -> فکورصنعت | F34: =VLOOKUP(D34,'لیست پرسنل'!$A$2:$D$1016,4,FALSE) -> تحقیق و توسعه فکور | G34: =VLOOKUP(D34,'لیست پرسنل'!$A$2:$E$1016,2,FALSE) -> 0 | H34: كنسانتره سنگ آهن بهاباد يزد | J34: مانيتور | K34: مانیتور جی پلاس 24-5JN | M34: 629332 | R34: به کارفرما فروخته شد | S34: 1404/06/11
A35: بهاباد يزد | B35: بهاباد يزد | D35: حسین عبدشاهی | E35: =VLOOKUP(D35,'لیست پرسنل'!$A$2:$D$1016,3,FALSE) -> فکورصنعت | F35: =VLOOKUP(D35,'لیست پرسنل'!$A$2:$D$1016,4,FALSE) -> تحقیق و توسعه فکور | G35: =VLOOKUP(D35,'لیست پرسنل'!$A$2:$E$1016,2,FALSE) -> 0 | H35: كنسانتره سنگ آهن بهاباد يزد | J35: گیرنده دیجیتال | K35: رسیور | M35: 629333 | R35: به کارفرما فروخته شد | S35: 1404/06/11
A36: بهاباد يزد | B36: بهاباد يزد | D36: حسین عبدشاهی | E36: =VLOOKUP(D36,'لیست پرسنل'!$A$2:$D$1016,3,FALSE) -> فکورصنعت | F36: =VLOOKUP(D36,'لیست پرسنل'!$A$2:$D$1016,4,FALSE) -> تحقیق و توسعه فکور | G36: =VLOOKUP(D36,'لیست پرسنل'!$A$2:$E$1016,2,FALSE) -> 0 | H36: كنسانتره سنگ آهن بهاباد يزد | J36: پرینتر | K36: پرینتر چندکاره لیزری کانن مدل SENSYS MF3010 | M36: 631077 | R36: به کارفرما فروخته شد | S36: 1404/06/11

Sheet خوابگاه 
A1: مشخصات سیستم های موجود درخوابگاه ها
A7: ردیف | B7: اپراتور | C7: شماره سیستم | D7: مدل مانیتور | E7: شماره سریال مانیتور | F7: کد اموال مانیتور | G7: کد اموال کیس | H7: متعلقات 1 | I7: سریال متعلقات | J7: کد اموال متعلقات | K7: متعلقات 2 | L7: سریال متعلقات | M7: کد اموال متعلقات
A8: 1 | B8: امیر علی سالار نیا نارسیس | C8: GG13C10 | D8: LG20" LED W2053S | E8: 0678027-204041103 | F8: 603954 | G8: 605221 | H8: Canon Laserjet LBP 6000B | I8: MXBA348017 | J8: 606000
A9: 2 | B9: امیر علی سالار نیا 15 خرداد | D9: AOC 19" 197VA-LCD | E9: AOCWHMAD84800089 | F9: 600016 | G9: 605714
A10: 3 | B10: خوابگاه صنایی | D10: LG Flatron 20EN33SS-B | E10: 310NDNUAD535 | F10: 601596 | G10: 603964
